Workbook

Sheet OT
B2: Screenshot de l'OT :

Sheet RACI
B2: Matrice RACI :
B4: Lot | C4: Sous-Lot | D4: CHAUVEL | E4: LE CHEVERE | F4: LEMOING
B5: Lot 1 : Analyse des besoins | D5: R | H5: R = Responsable
C6: Lot 1.1 : Recenser les règles du gala | D6: CI | E6: RA | F6: CI | H6: A = Acteur
C7: Lot 1.1.1 : Règles de gestion des invités | D7: A | E7: R | F7: A | H7: C = Consulté
C8: Lot 1.1.2 : Règles de gestion des tables | D8: CI | E8: RA | F8: CI | H8: I = Informé
C10: Lot 1.2 : Identifier les fonctions attendues | D10: A | E10: CI | F10: R
C11: Lot 1.2.1 : Relier une table à une personne ou groupe de personne | D11: A | E11: CI | F11: R
C12: Lot 1.2.1.1 : Lier une personne à un table | D12: A | E12: CI | F12: R
C13: Lot 1.2.1.2 : Modifier la table d'une personne | D13: A | E13: CI | F13: R
C14: Lot 1.2.1.3 : Afficher les personnes d'une table | D14: A | E14: A | F14: R
C15: Lot 1.2.1.4 : Supprimer la personne d'une table | D15: CI | E15: A | F15: R
C16: Lot 1.2.2 : Afficher le plan pour les personnes chargées de placer les gens | D16: CI | E16: A | F16: R
C17: Lot 1.2.2.1 : Afficher le nom et prénom des personnes par table | D17: CI | E17: A | F17: R
C19: Lot 1.2.3 : Modifier le plan | D19: CI | E19: A | F19: R
C20: Lot 1.2.3.1 : Supprimer une/un personne/groupe de personne | D20: CI | E20: A | F20: R
C21: Lot 1.2.3.2 : Ajouter une/un personne/groupe de personne | D21: CI | E21: A | F21: R
C22: Lot 1.2.3.3 : Déplacer une/un personne/groupe de personne | D22: CI | E22: A | F22: R
... C26: Lot 1.3.1 : le PC de l'entrée | D26: CI | E26: A | F26: R
B29: Lot 2 : Conception | E29: R
C30: Lot 2.1 : Modéliser l'interface | D30: CI | E30: RA | F30: A
C31: Lot 2.1.1 : Modéliser les contraintes | D31: CI | E31: RA | F31: A
C32: Lot 2.1.2 : Modéliser les personnes | D32: CI | E32: RA | F32: A
C33: Lot 2.1.2.1 : Modéliser les fonctions CRUD d'une personne | D33: CI | E33: RA | F33: A
C34: Lot 2.1.3 : Modéliser les tables | D34: CI | E34: RA | F34: A
C35: Lot 2.1.3.1 : Modéliser les fonctions CRUD d'une table | D35: CI | E35: RA | F35: A
C36: Lot 2.1.4 : Modéliser les fonctionnalitées | D36: CI | E36: RA | F36: A
C38: Lot 2.2 : Modéliser les éléments | D38: RA | E38: CI | F38: A
C39: Lot 2.2.1 : Modéliser les personnes | D39: RA | E39: CI | F39: A
C40: Lot 2.2.2 : Modéliser les groupes de personnes | D40: RA | E40: CI | F40: A
C41: Lot 2.2.3 : Modéliser les tables | D41: RA | E41: CI | F41: A
C42: Lot 2.2.3.1 : Modéliser les groupes de 6 personnes | D42: CI | E42: A | F42: R
... C49: Lot 2.3.1 : Gestion sur les tables | D49: CI | E49: RA | F49: C
B52: Lot 3 : Développement | D52: R
C53: Lot 3.1 : Développement de l'interface | D53: R | E53: A | F53: A
C54: Lot 3.1.1 : Fichier FXML de l'interface | D54: R | E54: A | F54: A
C55: Lot 3.1.2 : Classe contrôleur de l'interface | D55: R | E55: A | F55: A
C56: Lot 3.1.3 : Classe Fenêtre de l'interface | D56: R | E56: A | F56: A
C57: Lot 3.1.4 : Classe Principale de l'interface | D57: R | E57: A | F57: A
C59: Lot 3.2 : Développement des éléments | D59: RA | E59: CI | F59: A
...

Sheet Charges
B2: Estimation des charges :
B4: Lot | C4: Sous-Lot | D4: a | E4: m | F4: p | G4: Estimation | H4: Coût
B5: Lot 1 : Analyse des besoins
C6: Lot 1.1 : Recenser les règles du gala
C7: Lot 1.1.1 : Règles de gestion des invités | D7: 1 | E7: 2 | F7: 2.5 | G7: =(Charges!$D7+4*Charges!$E7+Charges!$F7)/6 -> 1.9166667 | H7: =Charges!$G7*60 -> 115
C8: Lot 1.1.2 : Règles de gestion des tables | D8: 1 | E8: 2 | F8: 2.5 | G8: =(Charges!$D8+4*Charges!$E8+Charges!$F8)/6 -> 1.9166667 | H8: =Charges!$G8*60 -> 115
C10: Lot 1.2 : Identifier les fonctions attendues
C11: Lot 1.2.1 : Relier une table à une personne ou groupe de personne
C12: Lot 1.2.1.1 : Lier une personne à un table | D12: 0.25 | E12: 0.5 | F12: 0.5 | G12: =(Charges!$D12+4*Charges!$E12+Charges!$F12)/6 -> 0.45833333 | H12: =Charges!$G12*60 -> 27.5
C13: Lot 1.2.1.2 : Modifier la table d'une personne | D13: 0.25 | E13: 0.5 | F13: 0.5 | G13: =(Charges!$D13+4*Charges!$E13+Charges!$F13)/6 -> 0.45833333 | H13: =Charges!$G13*60 -> 27.5
C14: Lot 1.2.1.3 : Afficher les personnes d'une table | D14: 0.25 | E14: 0.5 | F14: 0.5 | G14: =(Charges!$D14+4*Charges!$E14+Charges!$F14)/6 -> 0.45833333 | H14: =Charges!$G14*60 -> 27.5
C15: Lot 1.2.1.4 : Supprimer la personne d'une table | D15: 0.25 | E15: 0.5 | F15: 0.5 | G15: =(Charges!$D15+4*Charges!$E15+Charges!$F15)/6 -> 0.45833333 | H15: =Charges!$G15*60 -> 27.5
C16: Lot 1.2.2 : Afficher le plan pour les personnes chargées de placer les gens
C17: Lot 1.2.2.1 : Afficher le nom et prénom des personnes par table | D17: 1 | E17: 1.5 | F17: 2 | G17: =(Charges!$D17+4*Charges!$E17+Charges!$F17)/6 -> 1.5 | H17: =Charges!$G17*60 -> 90
C18: Lot 1.2.3 : Modifier le plan
C19: Lot 1.2.3.1 : Supprimer une/un personne/groupe de personne | D19: 0.25 | E19: 0.5 | F19: 0.5 | G19: =(Charges!$D19+4*Charges!$E19+Charges!$F19)/6 -> 0.45833333 | H19: =Charges!$G19*60 -> 27.5
C20: Lot 1.2.3.2 : Ajouter une/un personne/groupe de personne | D20: 0.25 | E20: 0.5 | F20: 0.5 | G20: =(Charges!$D20+4*Charges!$E20+Charges!$F20)/6 -> 0.45833333 | H20: =Charges!$G20*60 -> 27.5
C21: Lot 1.2.3.3 : Déplacer une/un personne/groupe de personne | D21: 0.25 | E21: 0.5 | F21: 0.5 | G21: =(Charges!$D21+4*Charges!$E21+Charges!$F21)/6 -> 0.45833333 | H21: =Charges!$G21*60 -> 27.5
C22: Lot 1.2.3.4 : Enlever une/un personne/groupe de personne | D22: 0.25 | E22: 0.5 | F22: 0.5 | G22: =(Charges!$D22+4*Charges!$E22+Charges!$F22)/6 -> 0.45833333 | H22: =Charges!$G22*60 -> 27.5
C24: Lot 1.3 : Définir les points d'affichage
C25: Lot 1.3.1 : le PC de l'entrée | D25: 4 | E25: 5 | F25: 6 | G25: =(Charges!$D25+4*Charges!$E25+Charges!$F25)/6 -> 5 | H25: =Charges!$G25*60 -> 300
B28: Lot 2 : Conception
C29: Lot 2.1 : Modéliser l'interface
C30: Lot 2.1.1 : Modéliser les contraintes | D30: 1 | E30: 1.5 | F30: 2.5 | G30: =(Charges!$D30+4*Charges!$E30+Charges!$F30)/6 -> 1.5833333 | H30: =Charges!$G30*60 -> 95
C31: Lot 2.1.2 : Modéliser les personnes
C32: Lot 2.1.2.1 : Modéliser les fonctions CRUD d'une personne | D32: 1 | E32: 1.5 | F32: 2.5 | G32: =(Charges!$D32+4*Charges!$E32+Charges!$F32)/6 -> 1.5833333 | H32: =Charges!$G32*60 -> 95
C33: Lot 2.1.3 : Modéliser les tables
C34: Lot 2.1.3.1 : Modéliser les fonctions CRUD d'une table | D34: 1 | E34: 1.5 | F34: 2.5 | G34: =(Charges!$D34+4*Charges!$E34+Charges!$F34)/6 -> 1.5833333 | H34: =Charges!$G34*60 -> 95
C35: Lot 2.1.4 : Modéliser les fonctionnalitées | D35: 1 | E35: 1 | F35: 2 | G35: =(Charges!$D35+4*Charges!$E35+Charges!$F35)/6 -> 1.1666667 | H35: =Charges!$G35*60 -> 70
C37: Lot 2.2 : Modéliser les éléments
C38: Lot 2.2.1 : Modéliser les personnes | D38: 1.5 | E38: 2.5 | F38: 2.25 | G38: =(Charges!$D38+4*Charges!$E38+Charges!$F38)/6 -> 2.2916667 | H38: =Charges!$G38*60 -> 137.5
C39: Lot 2.2.2 : Modéliser les groupes de personnes
C40: Lot 2.2.2.1 : Modéliser les groupes de 6 personnes | D40: 1 | E40: 1.25 | F40: 1 | G40: =(Charges!$D40+4*Charges!$E40+Charges!$F40)/6 -> 1.1666667 | H40: =Charges!$G40*60 -> 70
C41: Lot 2.2.2.2 : Modéliser les groupes de 12 personnes | D41: 1 | E41: 1.25 | F41: 1 | G41: =(Charges!$D41+4*Charges!$E41+Charges!$F41)/6 -> 1.1666667 | H41: =Charges!$G41*60 -> 70
C42: Lot 2.2.3 : Modéliser les tables | D42: 1.5 | E42: 2.5 | F42: 2.25 | G42: =(Charges!$D42+4*Charges!$E42+Charges!$F42)/6 -> 2.2916667 | H42: =Charges!$G42*60 -> 137.5
C43: Lot 2.2.4 : Modéliser les groupes de tables
C44: Lot 2.2.4.1 : Modéliser les tables de 6 personnes | D44: 1 | E44: 1.25 | F44: 1 | G44: =(Charges!$D44+4*Charges!$E44+Charges!$F44)/6 -> 1.1666667 | H44: =Charges!$G44*60 -> 70
C45: Lot 2.2.4.2 : Modéliser les tables de 12 personnes | D45: 1 | E45: 1.25 | F45: 1 | G45: =(Charges!$D45+4*Charges!$E45+Charges!$F45)/6 -> 1.1666667 | H45: =Charges!$G45*60 -> 70
C47: Lot 2.3 : Définir les règles de gestion
C48: Lot 2.3.1 : Gestion sur les tables | D48: 5 | E48: 7 | F48: 9 | G48: =(Charges!$D48+4*Charges!$E48+Charges!$F48)/6 -> 7 | H48: =Charges!$G48*60 -> 420
...
